Workbook

Sheet 00_INSTRUCCIONES
A1: PLANILLA MAESTRA DE EVALUACIÓN — TFG
A3: Propósito | B3: Esta planilla es el instrumento práctico de evaluación del TFG. Reúne las evidencias del baseline y del pipeline IA, aplica las métricas definidas en los capítulos 4 y 5, y calcula los resultados que después se explican en el capítulo de análisis.
A4: Alcance | B4: Política híbrida de evaluación: 7 evaluaciones R1 baseline (una por familia, con Seguimiento agregado en una fila por sprint) + 21 evaluaciones R1 pipeline (7 familias × 3 runs) = 28 evaluaciones R1 totales.
A5: Cómo usar (orden) | B5: 1) Revisar 01_A1_A2_inventario (A1/A2: artefactos IA y baseline). 2) Completar 02_R1_sintesis_artefactos y sus subinstrumentos R1: 03_R1_M1_checklist, 03b_R1_M1_resumen, 04_R1_M4_items y 05_R1_M3_contradicciones. 3) Revisar 06_P1_P2_pruebas (P1 validación técnica final + P2 checklist funcional). 4) Revisar 07_T1_T2_T3_tiempos (T1 ejecución automática IA, T2 esfuerzo humano/gate IA, T3 tiempos baseline). 5) Revisar 08_I1_incidencias (I1 incidencias). 6) Revisar 09_VD5_reproducibilidad (métricas M19-M21 derivadas de evidencias del caso IA). 7) Usar 10_AGREGADOS como lectura consolidada; algunas interpretaciones siguen requiriendo juicio cualitativo.
A7: Mapa de hojas, métricas y variables.
A8: Hoja | B8: Métricas | C8: VD | D8: Hipótesis / Rol
A9: 02_R1_sintesis_artefactos (+ 03, 03b, 04, 05) | B9: M1, M3, M4, M5 | C9: VD1 | D9: H2 (M1, M3, M4); M5 paralela, no contrasta H2
A10: 06_P1_P2_pruebas | B10: M6, M7, M-operatividad | C10: VD2 | D10: Criterio mínimo de comparabilidad, sin hipótesis
A11: 07_T1_T2_T3_tiempos | B11: M17 principal; M15, M18 auxiliares; M16 descriptiva | C11: VD4 | D11: H1
A12: 08_I1_incidencias | B12: M14 principal; M9, M10, M11, M12 auxiliares; M13 descriptiva | C12: VD3 | D12: H3
A13: 09_VD5_reproducibilidad | B13: M19, M20, M21 | C13: VD5 | D13: Caracterización del caso IA, sin hipótesis
A14: 08b_aux_bitacora_decisiones | B14: — | C14: — | D14: Bitácora del instrumento; no contrasta hipótesis
A16: Código de colores | B16: Amarillo = celda manual (input). Verde = celda calculada. Azul claro = pipeline. Naranja claro = baseline.
A17: Rúbricas y escalas. | B17: 1) M1 ordinal 0–3: 0 ausente, 1 parcial (<50 % o falta esencial), 2 sustancial (50–90 %), 3 completo (≥90 % + todos los esenciales). 2) M3 ordinal 0–3: 0 contradictorio (factual mayor o ≥3 contradicciones núcleo), 1 inconsistente (factual menor o 2–3 tipos), 2 coherente con fallos menores (≤2 terminológicas/granularidad), 3 coherente. 3) M4 porcentaje con cuatro tramos: 0–25 ausente/residual, 25–50 parcial, 50–75 sustancial, 75–100 alta. 4) M5 ordinal 0–4: suma directa de G1 (decisión), G2 (cambio), G3 (incidencia), G4 (aprobación/gate). 5) M-operatividad: 0 no arranca, 1 arranca pero flujo incompleto, 2 arranca y flujo mínimo completo.
A18: Reglas de evaluación | B18: 1) Regla 7 (cap. 4): toda evidencia se etiqueta como Original, Reconstruida o No disponible. 2) Criterio conservador (regla 3 del Anexo C): ante ambigüedad, contar como NO satisfecho y anotar. 3) Matching M4 baseline: textual con ≥3 palabras clave del dominio o mención literal de la función. 4) Matching M4 pipeline: ID explícito (booleano). 5) Si N < 3 ítems en una familia, M4 no se calcula; se reporta como tal. 6) Incidencias sistemáticas del pipeline (patrones replicados en los tres runs) se contabilizan una sola vez por patrón, marcando los runs afectados. (O: «se contabilizan una vez por run», según decidas).
A19: Hipótesis y criterio de veredicto. | B19: 1) H1 (VD4): confirmada si M17 pipeline < M17 baseline. Parcialmente sostenida si la ventaja existe pero depende de reconstrucción con incertidumbre. 2) H2 (VD1): confirmada si no aparece diferencia sustantiva desfavorable en M1/M3/M4 a través de las cinco familias. Parcialmente sostenida si la desventaja queda acotada a una dimensión. Rechazada si afecta a varias dimensiones. 3) H3 (VD3): confirmada si M14 pipeline < M14 baseline y M13 > 50 % (más de la mitad detectadas en gate humano). 4) VD2, VD5 y métricas descriptivas no tienen veredicto de hipótesis.

Sheet 01_A1_A2_inventario
A1: A1/A2 — Inventario maestro de artefactos IA y baseline
A3: ID | B3: Caso | C3: Run | D3: Familia | E3: Artefacto | F3: Ruta | G3: Regla 7 (Original / Reconstr. / No disp.) | H3: Estado evaluación | I3: Observaciones
A4: ART-B-REQ | B4: Baseline | C4: — | D4: Requisitos | E4: Registro Requisitos + Matriz Trazabilidad | F4: resultados_baseline\REGISTRO DE REQUISITOS.pdf + resultados_baseline\MATRIZ TRAZABILIDAD DE REQUISITOS.pdf | G4: Original | H4: Evaluado | I4: Fuente completa baseline localizada en 04_codigo/04a_casoBase/documentacion: REGISTRO DE REQUISITOS.pdf y MATRIZ TRAZABILIDAD DE REQUISITOS.pdf. Actas Patrocinador 1-4 sirven como evidencia auxiliar de cambios y aceptacion de alcance.
A5: ART-B-PLAN | B5: Baseline | C5: — | D5: Planificación | E5: Sprint Plannings + Product Backlogs S1-S2-S3 | F5: resultados_baseline\Sprint 1 - Planning.pdf + resultados_baseline\Sprint 2 - Planning.pdf + resultados_baseline\Sprint 3 - Planning.pdf + resultados_baseline\Sprint 1 - Product Backlog.pdf + resultados_baseline\Sprint 2 - Product Backlog.pdf + resultados_baseline\Sprint 3 - Product Backlog.pdf | G5: Original | H5: Evaluado | I5: Familia agregada: 3 sprints evaluados como conjunto. Fuente completa baseline localizada en documentacion/EJECUCION/Sprint 1-3. Fuentes auxiliares H1/planificacion: REGISTRO DE RIESGOS, CRONOGRAMA Y PRESUPUESTO, DICCIONARIO EDT, ATRIBUTOS DE ACTIVIDAD y PLAN DE GESTION DEL CRONOGRAMA.
A6: ART-B-DIS | B6: Baseline | C6: — | D6: Diseño técnico | E6: Auditoría posthoc 02_ARQUITECTURA + 03_MODELO_DATOS | F6: resultados_baseline\02_ARQUITECTURA.md + resultados_baseline\03_MODELO_DE_DATOS.md | G6: Reconstruida | H6: Evaluado | I6: Asimetria estructural mayor: baseline no produjo diseno tecnico original. Evidencia reconstruida principal y auxiliar localizada en documentacion/DISENO TECNICO (RECONSTRUIDO).
A7: ART-B-SEG-S1 | B7: Baseline | C7: — | D7: Seguimiento | E7: Sprint Review 1 + Retrospective 1 | F7: resultados_baseline\Sprint 1 - Review.pdf + resultados_baseline\Sprint 1 - Retrospetive.pdf | G7: Original | H7: Evaluado | I7: Fuente completa baseline: 04_codigo\04a_casoBase\documentacion\EJECUCIÓN\Sprint 1\Sprint 1 - Review.pdf + 04_codigo\04a_casoBase\documentacion\EJECUCIÓN\Sprint 1\Sprint 1 - Retrospetive.pdf. Evidencia auxiliar de gobernanza/incidencias: 04_codigo\04a_casoBase\documentacion\EJECUCIÓN\REGISTRO DE INCIDENCIAS.pdf + 04_codigo\04a_casoBase\documentacion\EJECUCIÓN\REGISTRO DE CAMBIOS.pdf + 04_codigo\04a_casoBase\documentacion\EJECUCIÓN\REGISTRO DE DECISIONES.pdf + 04_codigo\04a_casoBase\documentacion\SEGUIMIENTO\Daily Scrum Sprint 1.pdf + 04_codigo\04a_casoBase\documentacion\SEGUIMIENTO\Daily Scrum Sprint 2.pdf + 04_codigo\04a_casoBase\documentacion\SEGUIMIENTO\Daily Scrum Sprint 3.pdf.
A8: ART-B-SEG-S2 | B8: Baseline | C8: — | D8: Seguimiento | E8: Sprint Review 2 + Retrospective 2 | F8: resultados_baseline\Sprint 2 - Review.pdf + resultados_baseline\Sprint 2 - Retrospetive.pdf | G8: Original | H8: Evaluado | I8: Fuente completa baseline: 04_codigo\04a_casoBase\documentacion\EJECUCIÓN\Sprint 2\Sprint 2 - Review.pdf + 04_codigo\04a_casoBase\documentacion\EJECUCIÓN\Sprint 2\Sprint 2 - Retrospetive.pdf. Evidencia auxiliar de gobernanza/incidencias: 04_codigo\04a_casoBase\documentacion\EJECUCIÓN\REGISTRO DE INCIDENCIAS.pdf + 04_codigo\04a_casoBase\documentacion\EJECUCIÓN\REGISTRO DE CAMBIOS.pdf + 04_codigo\04a_casoBase\documentacion\EJECUCIÓN\REGISTRO DE DECISIONES.pdf + 04_codigo\04a_casoBase\documentacion\SEGUIMIENTO\Daily Scrum Sprint 1.pdf + 04_codigo\04a_casoBase\documentacion\SEGUIMIENTO\Daily Scrum Sprint 2.pdf + 04_codigo\04a_casoBase\documentacion\SEGUIMIENTO\Daily Scrum Sprint 3.pdf.
A9: ART-B-SEG-S3 | B9: Baseline | C9: — | D9: Seguimiento | E9: Sprint Review 3 + Retrospective 3 | F9: resultados_baseline\Sprint 3 - Review.pdf + resultados_baseline\Sprint 3 - Retrospetive.pdf | G9: Original | H9: Evaluado | I9: Fuente completa baseline: 04_codigo\04a_casoBase\documentacion\EJECUCIÓN\Sprint 3\Sprint 3 - Review.pdf + 04_codigo\04a_casoBase\documentacion\EJECUCIÓN\Sprint 3\Sprint 3 - Retrospetive.pdf. Evidencia auxiliar de gobernanza/incidencias: 04_codigo\04a_casoBase\documentacion\EJECUCIÓN\REGISTRO DE INCIDENCIAS.pdf + 04_codigo\04a_casoBase\documentacion\EJECUCIÓN\REGISTRO DE CAMBIOS.pdf + 04_codigo\04a_casoBase\documentacion\EJECUCIÓN\REGISTRO DE DECISIONES.pdf + 04_codigo\04a_casoBase\documentacion\SEGUIMIENTO\Daily Scrum Sprint 1.pdf + 04_codigo\04a_casoBase\documentacion\SEGUIMIENTO\Daily Scrum Sprint 2.pdf + 04_codigo\04a_casoBase\documentacion\SEGUIMIENTO\Daily Scrum Sprint 3.pdf.
A10: ART-B-CIE | B10: Baseline | C10: — | D10: Cierre | E10: Lecciones Aprendidas + Informe de cierre | F10: resultados_baseline\Lecciones aprendidas.pdf + resultados_baseline\Informe de cierre.pdf | G10: Original | H10: Evaluado | I10: Fuente completa baseline: 04_codigo\04a_casoBase\documentacion\CIERRE\Lecciones aprendidas.pdf + 04_codigo\04a_casoBase\documentacion\CIERRE\Informe de cierre.pdf. Evidencia auxiliar de cierre/seguimiento: 04_codigo\04a_casoBase\documentacion\SEGUIMIENTO\Cierre\Informe de Seguimiento - Cierre.pdf + 04_codigo\04a_casoBase\documentacion\SEGUIMIENTO\Cierre\Valor Ganado Cierre.pdf + 04_codigo\04a_casoBase\documentacion\SEGUIMIENTO\Cierre\Informe de Costos - Cierre.pdf + 04_codigo\04a_casoBase\documentacion\CIERRE\PROJECT CIERRE.pdf.
A11: ART-run_01-REQ | B11: Pipeline | C11: run_01 | D11: Requisitos | E11: registro_requisitos.json + .md | F11: resultados_pipeline\IA_OFICIAL_01\02_artefactos_generados\registro_requisitos.json + resultados_pipeline\IA_OFICIAL_01\02_artefactos_generados\registro_requisitos.md | G11: Original | H11: Evaluado
A12: ART-run_01-PLAN | B12: Pipeline | C12: run_01 | D12: Planificación | E12: backlog + plan_sprints + riesgos | F12: resultados_pipeline\IA_OFICIAL_01\02_artefactos_generados\backlog.json + resultados_pipeline\IA_OFICIAL_01\02_artefactos_generados\plan_sprints.json + resultados_pipeline\IA_OFICIAL_01\02_artefactos_generados\riesgos.json (+ versiones .md) | G12: Original | H12: Evaluado
A13: ART-run_01-DIS | B13: Pipeline | C13: run_01 | D13: Diseño técnico | E13: diseno_tecnico.json + .md | F13: resultados_pipeline\IA_OFICIAL_01\02_artefactos_generados\diseno_tecnico.json + resultados_pipeline\IA_OFICIAL_01\02_artefactos_generados\diseno_tecnico.md | G13: Original | H13: Evaluado
A14: ART-run_01-SEG-S1 | B14: Pipeline | C14: run_01 | D14: Seguimiento | E14: review_sprint_1.json + .md | F14: resultados_pipeline\IA_OFICIAL_01\03_sprints\review_sprint_1.json + resultados_pipeline\IA_OFICIAL_01\03_sprints\review_sprint_1.md | G14: Original | H14: Evaluado
A15: ART-run_01-SEG-S2 | B15: Pipeline | C15: run_01 | D15: Seguimiento | E15: review_sprint_2.json + .md | F15: resultados_pipeline\IA_OFICIAL_01\03_sprints\review_sprint_2.json + resultados_pipeline\IA_OFICIAL_01\03_sprints\review_sprint_2.md | G15: Original | H15: Evaluado
A16: ART-run_01-SEG-S3 | B16: Pipeline | C16: run_01 | D16: Seguimiento | E16: review_sprint_3.json + .md | F16: resultados_pipeline\IA_OFICIAL_01\03_sprints\review_sprint_3.json + resultados_pipeline\IA_OFICIAL_01\03_sprints\review_sprint_3.md | G16: Original | H16: Evaluado
A17: ART-run_01-CIE | B17: Pipeline | C17: run_01 | D17: Cierre | E17: lecciones_aprendidas.md + review_final.md + readme.md | F17: resultados_pipeline\IA_OFICIAL_01\04_cierre\lecciones_aprendidas.md + resultados_pipeline\IA_OFICIAL_01\00_manifest\review_final.md + resultados_pipeline\IA_OFICIAL_01\04_cierre\readme.md | G17: Original | H17: Evaluado
A18: ART-run_02-REQ | B18: Pipeline | C18: run_02 | D18: Requisitos | E18: registro_requisitos.json + .md | F18: resultados_pipeline\IA_OFICIAL_02\02_artefactos_generados\registro_requisitos.json + resultados_pipeline\IA_OFICIAL_02\02_artefactos_generados\registro_requisitos.md | G18: Original | H18: Evaluado
A19: ART-run_02-PLAN | B19: Pipeline | C19: run_02 | D19: Planificación | E19: backlog + plan_sprints + riesgos | F19: resultados_pipeline\IA_OFICIAL_02\02_artefactos_generados\backlog.json + resultados_pipeline\IA_OFICIAL_02\02_artefactos_generados\plan_sprints.json + resultados_pipeline\IA_OFICIAL_02\02_artefactos_generados\riesgos.json (+ versiones .md) | G19: Original | H19: Evaluado
A20: ART-run_02-DIS | B20: Pipeline | C20: run_02 | D20: Diseño técnico | E20: diseno_tecnico.json + .md | F20: resultados_pipeline\IA_OFICIAL_02\02_artefactos_generados\diseno_tecnico.json + resultados_pipeline\IA_OFICIAL_02\02_artefactos_generados\diseno_tecnico.md | G20: Original | H20: Evaluado
A21: ART-run_02-SEG-S1 | B21: Pipeline | C21: run_02 | D21: Seguimiento | E21: review_sprint_1.json + .md | F21: resultados_pipeline\IA_OFICIAL_02\03_sprints\review_sprint_1.json + resultados_pipeline\IA_OFICIAL_02\03_sprints\review_sprint_1.md | G21: Original | H21: Evaluado
A22: ART-run_02-SEG-S2 | B22: Pipeline | C22: run_02 | D22: Seguimiento | E22: review_sprint_2.json + .md | F22: resultados_pipeline\IA_OFICIAL_02\03_sprints\review_sprint_2.json + resultados_pipeline\IA_OFICIAL_02\03_sprints\review_sprint_2.md | G22: Original | H22: Evaluado
... A31: ART-run_03-CIE | B31: Pipeline | C31: run_03 | D31: Cierre | E31: lecciones_aprendidas.md + review_final.md + readme.md | F31: resultados_pipeline\IA_OFICIAL_03\04_cierre\lecciones_aprendidas.md + resultados_pipeline\IA_OFICIAL_03\00_manifest\review_final.md + resultados_pipeline\IA_OFICIAL_03\04_cierre\readme.md | G31: Original | H31: Evaluado

Sheet 03_R1_M1_checklist
A1: R1/M1 — Checklist por familia y artefacto (cobertura)
A2: Marca en cada columna SI el elemento está presente. Las columnas finales calculan cobertura. Esenciales con asterisco (*): si falta alguno, M1 baja a nivel 1.
A4: ID artefacto | B4: Familia | C4: Elemento esperado | D4: Esencial | E4: Presente (1/0) | F4: Evidencia (cita/ubicación)
A5: ART-B-REQ | B5: Requisitos | C5: Declaración de propósito / brief de referencia * | D5: Sí | E5: 1 | F5: 04_codigo\04a_casoBase\documentacion\PLANIFICACIÓN\REGISTROS\REGISTRO DE REQUISITOS.pdf + 04_codigo\04a_casoBase\documentacion\PLANIFICACIÓN\TRAZABILIDAD\MATRIZ TRAZABILIDAD DE REQUISITOS.pdf
A6: ART-B-REQ | B6: Requisitos | C6: Conjunto de RF con ID, descripción y prioridad * | D6: Sí | E6: 1 | F6: 04_codigo\04a_casoBase\documentacion\PLANIFICACIÓN\REGISTROS\REGISTRO DE REQUISITOS.pdf + 04_codigo\04a_casoBase\documentacion\PLANIFICACIÓN\TRAZABILIDAD\MATRIZ TRAZABILIDAD DE REQUISITOS.pdf
A7: ART-B-REQ | B7: Requisitos | C7: Conjunto de RNF con misma estructura * | D7: Sí | E7: 1 | F7: 04_codigo\04a_casoBase\documentacion\PLANIFICACIÓN\REGISTROS\REGISTRO DE REQUISITOS.pdf + 04_codigo\04a_casoBase\documentacion\PLANIFICACIÓN\TRAZABILIDAD\MATRIZ TRAZABILIDAD DE REQUISITOS.pdf
A8: ART-B-REQ | B8: Requisitos | C8: Cobertura mínima de funciones críticas del brief (auth/cat/reserva/admin) * | D8: Sí | E8: 1 | F8: 04_codigo\04a_casoBase\documentacion\PLANIFICACIÓN\REGISTROS\REGISTRO DE REQUISITOS.pdf + 04_codigo\04a_casoBase\documentacion\PLANIFICACIÓN\TRAZABILIDAD\MATRIZ TRAZABILIDAD DE REQUISITOS.pdf
A9: ART-B-REQ | B9: Requisitos | C9: Declaración explícita de exclusiones | D9: No | E9: 1 | F9: 04_codigo\04a_casoBase\documentacion\PLANIFICACIÓN\REGISTROS\REGISTRO DE REQUISITOS.pdf + 04_codigo\04a_casoBase\documentacion\PLANIFICACIÓN\TRAZABILIDAD\MATRIZ TRAZABILIDAD DE REQUISITOS.pdf + 04_codigo\04a_casoBase\documentacion\INICIO\ACTA DE CONSTITUCIÓN.pdf + 04_codigo\04a_casoBase\documentacion\INICIO\REGISTRO DE SUPUESTOS.pdf + 04_codigo\04a_casoBase\documentacion\PLANIFICACIÓN\LINEAS BASE\ENUNCIADO DEL ALCANCE.pdf
A10: ART-B-REQ | B10: Requisitos | C10: Registro de supuestos y restricciones | D10: No | E10: 1 | F10: 04_codigo\04a_casoBase\documentacion\PLANIFICACIÓN\REGISTROS\REGISTRO DE REQUISITOS.pdf + 04_codigo\04a_casoBase\documentacion\PLANIFICACIÓN\TRAZABILIDAD\MATRIZ TRAZABILIDAD DE REQUISITOS.pdf + 04_codigo\04a_casoBase\documentacion\INICIO\ACTA DE CONSTITUCIÓN.pdf + 04_codigo\04a_casoBase\documentacion\INICIO\REGISTRO DE SUPUESTOS.pdf + 04_codigo\04a_casoBase\documentacion\PLANIFICACIÓN\LINEAS BASE\ENUNCIADO DEL ALCANCE.pdf
A11: ART-B-REQ | B11: Requisitos | C11: Criterios genéricos de aceptación a nivel de proyecto | D11: No | E11: 1 | F11: 04_codigo\04a_casoBase\documentacion\PLANIFICACIÓN\REGISTROS\REGISTRO DE REQUISITOS.pdf + 04_codigo\04a_casoBase\documentacion\PLANIFICACIÓN\TRAZABILIDAD\MATRIZ TRAZABILIDAD DE REQUISITOS.pdf
A12: ART-B-PLAN | B12: Planificación | C12: Descomposición del alcance en HU con ID/descripción/prioridad * | D12: Sí | E12: 0 | F12: 04_codigo\04a_casoBase\documentacion\EJECUCIÓN\Sprint 1\Sprint 1 - Planning.pdf + 04_codigo\04a_casoBase\documentacion\EJECUCIÓN\Sprint 2\Sprint 2 - Planning.pdf + 04_codigo\04a_casoBase\documentacion\EJECUCIÓN\Sprint 3\Sprint 3 - Planning.pdf + 04_codigo\04a_casoBase\documentacion\EJECUCIÓN\Sprint 1\Sprint 1 - Product Backlog.pdf + 04_codigo\04a_casoBase\documentacion\EJECUCIÓN\Sprint 2\Sprint 2 - Product Backlog.pdf + 04_codigo\04a_casoBase\documentacion\EJECUCIÓN\Sprint 3\Sprint 3 - Product Backlog.pdf
A13: ART-B-PLAN | B13: Planificación | C13: Asignación de HU a sprints con objetivo declarado * | D13: Sí | E13: 0 | F13: 04_codigo\04a_casoBase\documentacion\EJECUCIÓN\Sprint 1\Sprint 1 - Planning.pdf + 04_codigo\04a_casoBase\documentacion\EJECUCIÓN\Sprint 2\Sprint 2 - Planning.pdf + 04_codigo\04a_casoBase\documentacion\EJECUCIÓN\Sprint 3\Sprint 3 - Planning.pdf + 04_codigo\04a_casoBase\documentacion\EJECUCIÓN\Sprint 1\Sprint 1 - Product Backlog.pdf + 04_codigo\04a_casoBase\documentacion\EJECUCIÓN\Sprint 2\Sprint 2 - Product Backlog.pdf + 04_codigo\04a_casoBase\documentacion\EJECUCIÓN\Sprint 3\Sprint 3 - Product Backlog.pdf
A14: ART-B-PLAN | B14: Planificación | C14: Entregable verificable por sprint * | D14: Sí | E14: 1 | F14: 04_codigo\04a_casoBase\documentacion\EJECUCIÓN\Sprint 1\Sprint 1 - Planning.pdf + 04_codigo\04a_casoBase\documentacion\EJECUCIÓN\Sprint 2\Sprint 2 - Planning.pdf + 04_codigo\04a_casoBase\documentacion\EJECUCIÓN\Sprint 3\Sprint 3 - Planning.pdf + 04_codigo\04a_casoBase\documentacion\EJECUCIÓN\Sprint 1\Sprint 1 - Product Backlog.pdf + 04_codigo\04a_casoBase\documentacion\EJECUCIÓN\Sprint 2\Sprint 2 - Product Backlog.pdf + 04_codigo\04a_casoBase\documentacion\EJECUCIÓN\Sprint 3\Sprint 3 - Product Backlog.pdf
A15: ART-B-PLAN | B15: Planificación | C15: Estimación de esfuerzo por HU * | D15: Sí | E15: 0 | F15: 04_codigo\04a_casoBase\documentacion\EJECUCIÓN\Sprint 1\Sprint 1 - Planning.pdf + 04_codigo\04a_casoBase\documentacion\EJECUCIÓN\Sprint 2\Sprint 2 - Planning.pdf + 04_codigo\04a_casoBase\documentacion\EJECUCIÓN\Sprint 3\Sprint 3 - Planning.pdf + 04_codigo\04a_casoBase\documentacion\EJECUCIÓN\Sprint 1\Sprint 1 - Product Backlog.pdf + 04_codigo\04a_casoBase\documentacion\EJECUCIÓN\Sprint 2\Sprint 2 - Product Backlog.pdf + 04_codigo\04a_casoBase\documentacion\EJECUCIÓN\Sprint 3\Sprint 3 - Product Backlog.pdf
A16: ART-B-PLAN | B16: Planificación | C16: Registro de riesgos con probabilidad/impacto/mitigación * | D16: Sí | E16: 1 | F16: 04_codigo\04a_casoBase\documentacion\EJECUCIÓN\Sprint 1\Sprint 1 - Planning.pdf + 04_codigo\04a_casoBase\documentacion\EJECUCIÓN\Sprint 2\Sprint 2 - Planning.pdf + 04_codigo\04a_casoBase\documentacion\EJECUCIÓN\Sprint 3\Sprint 3 - Planning.pdf + 04_codigo\04a_casoBase\documentacion\EJECUCIÓN\Sprint 1\Sprint 1 - Product Backlog.pdf + 04_codigo\04a_casoBase\documentacion\EJECUCIÓN\Sprint 2\Sprint 2 - Product Backlog.pdf + 04_codigo\04a_casoBase\documentacion\EJECUCIÓN\Sprint 3\Sprint 3 - Product Backlog.pdf + 04_codigo\04a_casoBase\documentacion\PLANIFICACIÓN\REGISTROS\REGISTRO DE RIESGOS.pdf
... A50: ART-B-CIE | B50: Cierre | C50: Identificación de causas raíz | D50: No | E50: 0 | F50: 04_codigo\04a_casoBase\documentacion\CIERRE\Lecciones aprendidas.pdf + 04_codigo\04a_casoBase\documentacion\CIERRE\Informe de cierre.pdf + 04_codigo\04a_casoBase\documentacion\SEGUIMIENTO\Cierre\Informe de Seguimiento - Cierre.pdf + 04_codigo\04a_casoBase\documentacion\SEGUIMIENTO\Cierre\Valor Ganado Cierre.pdf + 04_codigo\04a_casoBase\documentacion\SEGUIMIENTO\Cierre\Informe de Costos - Cierre.pdf + 04_codigo\04a_casoBase\documentacion\CIERRE\PROJECT CIERRE.pdf
A51: ART-run_01-REQ | B51: Requisitos | C51: Declaración de propósito / brief de referencia * | D51: Sí | E51: 1
A52: ART-run_01-REQ | B52: Requisitos | C52: Conjunto de RF con ID, descripción y prioridad * | D52: Sí | E52: 1
A53: ART-run_01-REQ | B53: Requisitos | C53: Conjunto de RNF con misma estructura * | D53: Sí | E53: 1
A54: ART-run_01-REQ | B54: Requisitos | C54: Cobertura mínima de funciones críticas del brief (auth/cat/reserva/admin) * | D54: Sí | E54: 1
A55: ART-run_01-REQ | B55: Requisitos | C55: Declaración explícita de exclusiones | D55: No | E55: 0
A56: ART-run_01-REQ | B56: Requisitos | C56: Registro de supuestos y restricciones | D56: No | E56: 0
A57: ART-run_01-REQ | B57: Requisitos | C57: Criterios genéricos de aceptación a nivel de proyecto | D57: No | E57: 0
A58: ART-run_01-PLAN | B58: Planificación | C58: Descomposición del alcance en HU con ID/descripción/prioridad * | D58: Sí | E58: 1
A59: ART-run_01-PLAN | B59: Planificación | C59: Asignación de HU a sprints con objetivo declarado * | D59: Sí | E59: 1
A60: ART-run_01-PLAN | B60: Planificación | C60: Entregable verificable por sprint * | D60: Sí | E60: 1
A61: ART-run_01-PLAN | B61: Planificación | C61: Estimación de esfuerzo por HU * | D61: Sí | E61: 0
A62: ART-run_01-PLAN | B62: Planificación | C62: Registro de riesgos con probabilidad/impacto/mitigación * | D62: Sí | E62: 1
... A188: ART-run_03-CIE | B188: Cierre | C188: Identificación de causas raíz | D188: No | E188: 0

Sheet 03b_R1_M1_resumen
A1: R1/M1 — Resumen automático de cobertura por artefacto
A3: ID artefacto | B3: Caso | C3: Familia | D3: N total elementos | E3: N satisfechos | F3: Cobertura (%) | G3: N esenciales | H3: Esenciales satisfechos | I3: Nivel M1 (calculado)
A4: ART-B-REQ | B4: Baseline | C4: Requisitos | D4: 7 | E4: =SUMIFS('03_R1_M1_checklist'!E:E,'03_R1_M1_checklist'!A:A,A4) | F4: =IF(D4>0,E4/D4*100,0) | G4: 4 | H4: =COUNTIFS('03_R1_M1_checklist'!A:A,A4,'03_R1_M1_checklist'!D:D,"Sí",'03_R1_M1_checklist'!E:E,1) | I4: =IF(E4="",0,IF(AND(F4>=90,H4=G4),3,IF(AND(F4>=50,H4=G4),2,IF(E4>0,1,0))))
A5: ART-B-PLAN | B5: Baseline | C5: Planificación | D5: 8 | E5: =SUMIFS('03_R1_M1_checklist'!E:E,'03_R1_M1_checklist'!A:A,A5) | F5: =IF(D5>0,E5/D5*100,0) | G5: 5 | H5: =COUNTIFS('03_R1_M1_checklist'!A:A,A5,'03_R1_M1_checklist'!D:D,"Sí",'03_R1_M1_checklist'!E:E,1) | I5: =IF(E5="",0,IF(AND(F5>=90,H5=G5),3,IF(AND(F5>=50,H5=G5),2,IF(E5>0,1,0))))
A6: ART-B-DIS | B6: Baseline | C6: Diseño técnico | D6: 7 | E6: =SUMIFS('03_R1_M1_checklist'!E:E,'03_R1_M1_checklist'!A:A,A6) | F6: =IF(D6>0,E6/D6*100,0) | G6: 4 | H6: =COUNTIFS('03_R1_M1_checklist'!A:A,A6,'03_R1_M1_checklist'!D:D,"Sí",'03_R1_M1_checklist'!E:E,1) | I6: =IF(E6="",0,IF(AND(F6>=90,H6=G6),3,IF(AND(F6>=50,H6=G6),2,IF(E6>0,1,0))))
A7: ART-B-SEG-S1 | B7: Baseline | C7: Seguimiento | D7: 6 | E7: =SUMIFS('03_R1_M1_checklist'!E:E,'03_R1_M1_checklist'!A:A,A7) | F7: =IF(D7>0,E7/D7*100,0) | G7: 4 | H7: =COUNTIFS('03_R1_M1_checklist'!A:A,A7,'03_R1_M1_checklist'!D:D,"Sí",'03_R1_M1_checklist'!E:E,1) | I7: =IF(E7="",0,IF(AND(F7>=90,H7=G7),3,IF(AND(F7>=50,H7=G7),2,IF(E7>0,1,0))))
A8: ART-B-SEG-S2 | B8: Baseline | C8: Seguimiento | D8: 6 | E8: =SUMIFS('03_R1_M1_checklist'!E:E,'03_R1_M1_checklist'!A:A,A8) | F8: =IF(D8>0,E8/D8*100,0) | G8: 4 | H8: =COUNTIFS('03_R1_M1_checklist'!A:A,A8,'03_R1_M1_checklist'!D:D,"Sí",'03_R1_M1_checklist'!E:E,1) | I8: =IF(E8="",0,IF(AND(F8>=90,H8=G8),3,IF(AND(F8>=50,H8=G8),2,IF(E8>0,1,0))))
A9: ART-B-SEG-S3 | B9: Baseline | C9: Seguimiento | D9: 6 | E9: =SUMIFS('03_R1_M1_checklist'!E:E,'03_R1_M1_checklist'!A:A,A9) | F9: =IF(D9>0,E9/D9*100,0) | G9: 4 | H9: =COUNTIFS('03_R1_M1_checklist'!A:A,A9,'03_R1_M1_checklist'!D:D,"Sí",'03_R1_M1_checklist'!E:E,1) | I9: =IF(E9="",0,IF(AND(F9>=90,H9=G9),3,IF(AND(F9>=50,H9=G9),2,IF(E9>0,1,0))))
A10: ART-B-CIE | B10: Baseline | C10: Cierre | D10: 6 | E10: =SUMIFS('03_R1_M1_checklist'!E:E,'03_R1_M1_checklist'!A:A,A10) | F10: =IF(D10>0,E10/D10*100,0) | G10: 4 | H10: =COUNTIFS('03_R1_M1_checklist'!A:A,A10,'03_R1_M1_checklist'!D:D,"Sí",'03_R1_M1_checklist'!E:E,1) | I10: =IF(E10="",0,IF(AND(F10>=90,H10=G10),3,IF(AND(F10>=50,H10=G10),2,IF(E10>0,1,0))))
A11: ART-run_01-REQ | B11: Pipeline | C11: Requisitos | D11: 7 | E11: =SUMIFS('03_R1_M1_checklist'!E:E,'03_R1_M1_checklist'!A:A,A11) | F11: =IF(D11>0,E11/D11*100,0) | G11: 4 | H11: =COUNTIFS('03_R1_M1_checklist'!A:A,A11,'03_R1_M1_checklist'!D:D,"Sí",'03_R1_M1_checklist'!E:E,1) | I11: =IF(E11="",0,IF(AND(F11>=90,H11=G11),3,IF(AND(F11>=50,H11=G11),2,IF(E11>0,1,0))))
A12: ART-run_01-PLAN | B12: Pipeline | C12: Planificación | D12: 8 | E12: =SUMIFS('03_R1_M1_checklist'!E:E,'03_R1_M1_checklist'!A:A,A12) | F12: =IF(D12>0,E12/D12*100,0) | G12: 5 | H12: =COUNTIFS('03_R1_M1_checklist'!A:A,A12,'03_R1_M1_checklist'!D:D,"Sí",'03_R1_M1_checklist'!E:E,1) | I12: =IF(E12="",0,IF(AND(F12>=90,H12=G12),3,IF(AND(F12>=50,H12=G12),2,IF(E12>0,1,0))))
A13: ART-run_01-DIS | B13: Pipeline | C13: Diseño técnico | D13: 7 | E13: =SUMIFS('03_R1_M1_checklist'!E:E,'03_R1_M1_checklist'!A:A,A13) | F13: =IF(D13>0,E13/D13*100,0) | G13: 4 | H13: =COUNTIFS('03_R1_M1_checklist'!A:A,A13,'03_R1_M1_checklist'!D:D,"Sí",'03_R1_M1_checklist'!E:E,1) | I13: =IF(E13="",0,IF(AND(F13>=90,H13=G13),3,IF(AND(F13>=50,H13=G13),2,IF(E13>0,1,0))))
A14: ART-run_01-SEG-S1 | B14: Pipeline | C14: Seguimiento | D14: 6 | E14: =SUMIFS('03_R1_M1_checklist'!E:E,'03_R1_M1_checklist'!A:A,A14) | F14: =IF(D14>0,E14/D14*100,0) | G14: 4 | H14: =COUNTIFS('03_R1_M1_checklist'!A:A,A14,'03_R1_M1_checklist'!D:D,"Sí",'03_R1_M1_checklist'!E:E,1) | I14: =IF(E14="",0,IF(AND(F14>=90,H14=G14),3,IF(AND(F14>=50,H14=G14),2,IF(E14>0,1,0))))
A15: ART-run_01-SEG-S2 | B15: Pipeline | C15: Seguimiento | D15: 6 | E15: =SUMIFS('03_R1_M1_checklist'!E:E,'03_R1_M1_checklist'!A:A,A15) | F15: =IF(D15>0,E15/D15*100,0) | G15: 4 | H15: =COUNTIFS('03_R1_M1_checklist'!A:A,A15,'03_R1_M1_checklist'!D:D,"Sí",'03_R1_M1_checklist'!E:E,1) | I15: =IF(E15="",0,IF(AND(F15>=90,H15=G15),3,IF(AND(F15>=50,H15=G15),2,IF(E15>0,1,0))))
... A31: ART-run_03-CIE | B31: Pipeline | C31: Cierre | D31: 6 | E31: =SUMIFS('03_R1_M1_checklist'!E:E,'03_R1_M1_checklist'!A:A,A31) | F31: =IF(D31>0,E31/D31*100,0) | G31: 4 | H31: =COUNTIFS('03_R1_M1_checklist'!A:A,A31,'03_R1_M1_checklist'!D:D,"Sí",'03_R1_M1_checklist'!E:E,1) | I31: =IF(E31="",0,IF(AND(F31>=90,H31=G31),3,IF(AND(F31>=50,H31=G31),2,IF(E31>0,1,0))))

Sheet 05_R1_M3_contradicciones
A1: R1/M3 — Registro de contradicciones detectadas
A2: Una fila por contradicción detectada. Tipos: Factual, Terminológica, Granularidad, Prioridad/estado. Mayor/Menor solo para factuales (mayor = afecta núcleo funcional, esencial del check-list de M1).
A4: ID artefacto | B4: ID contradicción | C4: Tipo | D4: Mayor/Menor (solo factual) | E4: Ubicación 1 | F4: Ubicación 2 | G4: Descripción | H4: Notas
A5: ART-B-REQ
A6: ART-B-REQ | B6: M3-B-REQ-01 | C6: Terminológica | E6: Registro de Requisitos (IDs RF13, RF15, RF19) | F6: Matriz de Trazabilidad (IDs RF13, RF15, RF19) | G6: RF13, RF15 y RF19 no aparecen con la misma identificación/etiqueta en ambos documentos: el mismo requisito recibe nomenclatura distinta entre Registro y Matriz.
A7: ART-B-REQ | B7: M3-B-REQ-02 | C7: Granularidad | E7: Registro de Requisitos (numeración tras RF16) | G7: La serie de identificadores salta numeración tras RF16, dejando huecos en la secuencia de RF; la lista de requisitos no mantiene un mismo nivel de granularidad en su indexación.
A8: ART-B-REQ | B8: M3-B-REQ-03 | C8: Granularidad | E8: Registro de Requisitos (RF19) | F8: Matriz de Trazabilidad / Product Backlogs S1-S3 | G8: RF19 queda sin correspondencia clara en Registro/backlogs: el requisito no se descompone ni se enlaza al mismo nivel de detalle que el resto.
A9: ART-B-PLAN
A10: ART-B-PLAN | B10: M3-B-PLAN-01 | C10: Terminológica | E10: Sprint Plannings S1-S2-S3 (encabezado / tipo documental) | G10: Algunos documentos de planning mantienen un tipo documental incorrecto en encabezado, confundiendo el rótulo del artefacto con su contenido.
A11: ART-B-PLAN | B11: M3-B-PLAN-02 | C11: Granularidad | E11: Sprint Planning Sx (decisión de pasarela/despliegue) | F11: Sprint Planning Sy / Informe de cierre | G11: Cambios de pasarela de pago y/o estrategia de despliegue entre sprints documentados a granularidad desigual: la decisión técnica no se refleja con el mismo nivel de detalle en plannings sucesivos, quedando solo parcialmente justificada en planning/cierre.
A13: ART-B-DIS
A17: ART-B-SEG-S1
A18: ART-B-SEG-S1 | B18: M3-B-SEG-S1-01 | C18: Terminológica | E18: Sprint Review 1 / Retrospective 1 (encabezado) | G18: Algunos encabezados identifican la review/retrospective como Sprint Planning: el mismo tipo de documento recibe rótulos distintos, lo que introduce ambigüedad sobre el tipo de artefacto. No afecta al contenido central.
A21: ART-B-SEG-S2
A22: ART-B-SEG-S2 | B22: M3-B-SEG-S2-01 | C22: Terminológica | E22: Sprint Review 2 / Retrospective 2 (encabezado) | G22: Encabezado/tipo de documento inconsistente con el contenido del artefacto: persiste la confusión Planning vs. Review/Retrospective del Sprint 1.
A25: ART-B-SEG-S3
A26: ART-B-SEG-S3 | B26: M3-B-SEG-S3-01 | C26: Factual | D26: Menor | E26: Retrospectiva Sprint 3 (fechas) | F26: Planning / Review Sprint 3 (fechas) | G26: Fechas declaradas en la retrospectiva del Sprint 3 no cuadran con las del planning/review del mismo sprint: dos elementos del artefacto afirman cosas incompatibles sobre el mismo aspecto temporal. Menor: no afecta al núcleo funcional del seguimiento.
A27: ART-B-SEG-S3 | B27: M3-B-SEG-S3-02 | C27: Terminológica | E27: Sprint Review 3 / Retrospective 3 (encabezado) | G27: Persistencia de encabezados no alineados con el tipo real de documento (Planning vs Review/Retrospective), análoga a S1 y S2.
A29: ART-B-CIE
A33: ART-run_01-REQ
A34: ART-run_01-REQ | B34: M3-run_01-REQ-01 | C34: Granularidad | E34: registro_requisitos.json / .md (campo prioridad) | G34: La priorización asignada a los RF/RNF es poco discriminante: la mayoría de los ítems recibe el mismo valor, lo que indica granularidad insuficiente en el atributo de prioridad. Observación no bloqueante registrada por Gate 1.
A35: ART-run_01-REQ | B35: M3-run_01-REQ-02 | C35: Granularidad | E35: registro_requisitos.json / .md (RNF de seguridad e importe) | G35: Granularidad limitada en los RNF de seguridad y de importe: requisitos que deberían desglosarse en varios ítems quedan agrupados en un único RNF.
A37: ART-run_01-PLAN
A38: ART-run_01-PLAN | B38: M3-run_01-PLAN-01 | C38: Granularidad | E38: backlog / plan_sprints (reparto entre sprints) | G38: Concentración de complejidad en un sprint frente a los otros: el reparto de HU no mantiene un nivel de complejidad homogéneo entre los tres sprints. Observación no bloqueante de Gate 2.
A39: ART-run_01-PLAN | B39: M3-run_01-PLAN-02 | C39: Granularidad | E39: Dockerfile (seed) / plan_sprints (uso de cron/Celery) | G39: Decisiones técnicas (seed en Dockerfile, posible exceso con cron/Celery) introducidas a un nivel de detalle distinto del que corresponde a un artefacto de planificación: mezcla de planificación de alto nivel con detalle de implementación. Observación no bloqueante de Gate 2.
A41: ART-run_01-DIS
A42: ART-run_01-DIS | B42: M3-run_01-DIS-01 | C42: Terminol?gica | E42: diseno_tecnico.json / .md (campo ImageField) | G42: ImageField aparece declarado como upload_to=barcos/ sin comillas; el dise?o usa una formulaci?n no alineada con la convenci?n del framework. Observaci?n menor de Gate 3.
A43: ART-run_01-DIS | B43: M3-run_01-DIS-02 | C43: Granularidad | E43: diseno_tecnico.json / .md (core/settings, core/urls) | G43: core/settings.py y core/urls.py pueden confundirse con el paquete de proyecto Django; la organizaci?n se documenta a un nivel distinto del resto de apps/componentes. Observaci?n menor de Gate 3.
A44: ART-run_01-DIS | B44: M3-run_01-DIS-03 | C44: Granularidad | E44: diseno_tecnico.json / .md (disponibilidad y rutas) | G44: La disponibilidad por fechas aparece tratada con menor precisi?n t?cnica de la esperada y logout se plantea como ruta GET; son observaciones de dise?o no bloqueantes registradas en Gate 3.
A45: ART-run_01-SEG-S1
A49: ART-run_01-SEG-S2
A53: ART-run_01-SEG-S3
A57: ART-run_01-CIE
A61: ART-run_02-REQ
A62: ART-run_02-REQ | B62: M3-run_02-REQ-01 | C62: Granularidad | E62: registro_requisitos.json / .md (roles) | G62: Los roles cliente y administrador no aparecen como requisito independiente, sino implícitos en otros ítems: omisión por granularidad insuficiente en la declaración de actores. Observación no bloqueante de Gate 1.
A65: ART-run_02-PLAN
A66: ART-run_02-PLAN | B66: M3-run_02-PLAN-01 | C66: Factual | D66: Menor | E66: plan_sprints (entregable Sprint 2) | F66: backlog (HU-16 asignada a Sprint 3) | G66: El entregable declarado para el Sprint 2 menciona la consulta por código, pero la HU-16 que materializa esa funcionalidad está asignada al Sprint 3: dos partes del artefacto afirman cosas incompatibles sobre cuándo se entrega esa funcionalidad. Menor: no afecta al núcleo del producto, solo a la planificación interna.
A69: ART-run_02-DIS
A70: ART-run_02-DIS | B70: M3-run_02-DIS-01 | C70: Terminológica | E70: diseno_tecnico.json / .md (campo ImageField) | G70: ImageField declarado como cadena en lugar de su tipo específico: el mismo concepto recibe una denominación de tipo distinta de la convención del framework. Observación menor de Gate 3.
A71: ART-run_02-DIS | B71: M3-run_02-DIS-02 | C71: Granularidad | E71: diseno_tecnico.json / .md (User propio, core/settings, disponibilidad por fechas) | G71: Observaciones técnicas agrupadas sobre granularidad desigual del diseño: User propio, organización de core/settings y cálculo de disponibilidad por fechas se documentan a niveles de detalle inconsistentes entre sí. Observaciones menores de Gate 3.
...

Sheet 04_R1_M4_items
A1: R1/M4 — Verificación ítem a ítem de trazabilidad
A2: Esta hoja documenta ítem a ítem los artefactos del baseline. La trazabilidad del pipeline se documenta mediante la capa automática descrita en el TFG y sus resultados agregados aparecen en las columnas K, L y M de 02_R1_sintesis_artefactos. Una fila por ítem del artefacto (RF/RNF/HU/etc.). Marca 1/0 si presenta enlace verificable aguas arriba y aguas abajo. Si la familia ocupa un extremo de la cadena, solo se exige una dirección.
A4: ID artefacto | B4: Item ID | C4: Item descripción corta | D4: Tipo matching (ID/textual) | E4: Aguas arriba (1/0) | F4: Aguas abajo (1/0) | G4: ¿Es extremo de cadena? (Si/No) | H4: Trazable (calc) | I4: Evidencia/cita | J4: Observaciones
A5: ART-B-REQ | B5: RF1 | C5: Barcos visibles para alquiler | D5: Textual | F5: 1 | G5: Sí | H5: =IF(F5=1,1,0) | I5: Matriz RF1 vincula barcos visibles con Front End y pruebas funcionales. Product Backlog S1/S2/S3 cita RF1 literal y lo marca Terminado.
A6: ART-B-REQ | B6: RNF1 | C6: Mecanismo simple para aumentar/disminuir tiempo de alquiler | D6: Textual | F6: 1 | G6: Sí | H6: =IF(F6=1,1,0) | I6: Matriz RNF1 vincula tiempo de alquiler con Front End y pruebas de satisfaccion. Product Backlog S1/S2/S3 cita RNF1 literal y lo marca Terminado.
A7: ART-B-REQ | B7: RF2 | C7: Categorias de barcos iguales a las que se ofertan | D7: Textual | F7: 1 | G7: Sí | H7: =IF(F7=1,1,0) | I7: Matriz RF2 vincula categorias de barcos con Front End/Back End. Product Backlog S1/S2/S3 cita RF2 literal y lo marca Terminado.
A8: ART-B-REQ | B8: RF3 | C8: Alquiler sin requerir inicio de sesion | D8: Textual | F8: 1 | G8: Sí | H8: =IF(F8=1,1,0) | I8: Matriz RF3 vincula alquiler sin sesion con Back End. Product Backlog S2/S3 cita RF3 literal; S3 lo marca Terminado.
A9: ART-B-REQ | B9: RNF2 | C9: Modificacion de datos de cuenta del cliente | D9: Textual | F9: 1 | G9: Sí | H9: =IF(F9=1,1,0) | I9: Matriz RNF2 vincula modificacion de datos de cuenta con Back End. Product Backlog S1/S2/S3 cita RNF2 literal y lo marca Terminado.
A10: ART-B-REQ | B10: RNF3 | C10: Seguridad percibida durante el proceso del alquiler | D10: Textual | F10: 1 | G10: Sí | H10: =IF(F10=1,1,0) | I10: Matriz RNF3 vincula seguridad del proceso con Front End y satisfaccion. Product Backlog S3 cita RNF3 literal y lo marca Terminado.
A11: ART-B-REQ | B11: RNF4 | C11: Página escrita en español | D11: Textual | F11: 1 | G11: Sí | H11: =IF(F11=1,1,0) | I11: Matriz RNF4 vincula idioma español con Front End/Back End. Product Backlog S1/S2/S3 cita RNF4 literal y lo marca Terminado.
A12: ART-B-REQ | B12: RF4 | C12: Identificación/login por correo y contraseña | D12: Textual | F12: 1 | G12: Sí | H12: =IF(F12=1,1,0) | I12: Matriz RF4 vincula login por correo/contraseña con Front End/Back End. Product Backlog S1/S2/S3 cita RF4 literal y lo marca Terminado.
A13: ART-B-REQ | B13: RF5 | C13: Acceso al tiempo restante de alquiler | D13: Textual | F13: 1 | G13: Sí | H13: =IF(F13=1,1,0) | I13: Matriz RF5 vincula tiempo restante de alquiler con Front End. Product Backlog S3 cita RF5 literal y lo marca Terminado.
A14: ART-B-REQ | B14: RF6 | C14: Barcos no disponibles claramente marcados | D14: Textual | F14: 1 | G14: Sí | H14: =IF(F14=1,1,0) | I14: Matriz RF6 vincula disponibilidad visible con Front End. Product Backlog S1/S2/S3 cita RF6 literal y lo marca Terminado.
A15: ART-B-REQ | B15: RNF5 | C15: Datos del barco: capacidad, imagen, categoria, fabricante y puerto | D15: Textual | F15: 1 | G15: Sí | H15: =IF(F15=1,1,0) | I15: Matriz RNF5 vincula datos del barco con Back End. Product Backlog S1/S2/S3 cita RNF5 literal y lo marca Terminado.
A16: ART-B-REQ | B16: RF7 | C16: Codigo de seguimiento asociado al alquiler, enviado por correo | D16: Textual | F16: 1 | G16: Sí | H16: =IF(F16=1,1,0) | I16: Matriz RF7 vincula codigo/correo de alquiler con Back End. Product Backlog S2/S3 cita RF7 y S3 lo marca Terminado.
... A21: ART-B-REQ | B21: RF12 | C21: Solicitud de datos de pago | D21: Textual | F21: 1 | G21: Sí | H21: =IF(F21=1,1,0) | I21: Matriz RF12 vincula datos de pago con Front End/Back End. Product Backlog S3 cita RF12 y lo marca Terminado.
A22: ART-B-REQ | B22: RF13 | C22: Estados del alquiler y pago posterior | D22: Textual | F22: 1 | G22: Sí | H22: =IF(F22=1,1,0) | I22: Matriz RF13 define PAGADO/PENDIENTE. Registro y Product Backlog S3 actualizan como RF13b con PAGADO, PENDIENTE DE PAGO, EN USO y DEVUELTO; S3 lo marca Terminado. | J22: ID evolucionado RF13 -> RF13b; trazable por funcion.
A23: ART-B-REQ | B23: RF14 | C23: Terminado proceso se envia un correo con datos de barco/puerto/importe | D23: Textual | F23: 1 | G23: Sí | H23: =IF(F23=1,1,0) | I23: Matriz RF14 vincula correo de finalizacion. Product Backlog S2/S3 cita RF14 y lo marca Terminado.
A24: ART-B-REQ | B24: RF15 | C24: Recordatorio de pago un dia antes del inicio de la reserva | D24: Textual | F24: 0 | G24: Sí | H24: =IF(F24=1,1,0) | I24: Matriz RF15 y Product Backlog S1/S2 lo incluyen como Won't. Sprint 3 Planning menciona RF15 en seguimiento de pedidos, pero Product Backlog S3 no conserva RF15 ni lo marca Terminado. | J24: Propuesto NO trazable: no queda evidencia de materializacion aguas abajo en backlog final.
A25: ART-B-REQ | B25: RF16 | C25: No devolucion de productos/alquileres | D25: Textual | F25: 1 | G25: Sí | H25: =IF(F25=1,1,0) | I25: Matriz RF16 vincula no devoluci?n con Front End/Back End. Product Backlog S1/S2/S3 cita RF16 no devolucion y lo marca Terminado.
A26: ART-B-REQ | B26: RNF6 | C26: Marca corporativa y politicas visibles | D26: Textual | F26: 1 | G26: Sí | H26: =IF(F26=1,1,0) | I26: Matriz RNF6 vincula marca/politicas con Front End. Product Backlog S1/S2/S3 cita RNF6 y lo marca Terminado.
A27: ART-B-REQ | B27: RO1 | C27: Manuales de usuario e instrucciones de puesta en produccion | D27: Textual | F27: 1 | G27: Sí | H27: =IF(F27=1,1,0) | I27: Matriz RO1 vincula documentacion final. Sprint 3 Planning incluye redactar manual e instrucciones de despliegue; Product Backlog S3 cita RO1 y lo marca Terminado.
A28: ART-B-REQ | B28: RO2 | C28: Uso de ciclo de vida hibrido | D28: Textual | F28: 1 | G28: Sí | H28: =IF(F28=1,1,0) | I28: Matriz RO2 vincula ciclo de vida hibrido con documentacion. Product Backlog S2/S3 cita RO2 y lo marca Terminado.
A29: ART-B-REQ | B29: RO3 | C29: Uso de plantillas proporcionadas por la organizacion | D29: Textual | F29: 1 | G29: Sí | H29: =IF(F29=1,1,0) | I29: Matriz RO3 vincula plantillas con documentacion. Product Backlog S2/S3 cita RO3 y lo marca Terminado.
A30: ART-B-REQ | B30: RF17 | C30: Usuarios registrados pueden ser clientes o administradores | D30: Textual | F30: 1 | G30: Sí | H30: =IF(F30=1,1,0) | I30: Matriz RF17 define roles cliente/administrador. Registro/Product Backlog usan la misma funcion con numeracion desplazada (RF16 en backlog), marcada Terminado. | J30: Trazable por funcion aunque hay desplazamiento de ID respecto a Registro/Backlog.
A31: ART-B-REQ | B31: RF18 | C31: Cliente ve productos y solo sus alquileres | D31: Textual | F31: 1 | G31: Sí | H31: =IF(F31=1,1,0) | I31: Matriz RF18 define visibilidad del cliente. Product Backlog S3 cita RF17 con la misma funci?n y lo marca Terminado. | J31: Trazable por funcion aunque hay desplazamiento de ID.
A32: ART-B-REQ | B32: RF19 | C32: Administrador ve/edita productos y revisa todos los alquileres | D32: Textual | F32: 1 | G32: Sí | H32: =IF(F32=1,1,0) | I32: Matriz RF19 define permisos de administrador. Registro/Product Backlog S3 contienen la misma funcion como RF18 y la marcan Terminado. | J32: Duda: ID RF19 no aparece en Registro/Backlog; propuesta trazable por coincidencia textual funcional segun 4.2.3.
A33: ART-B-PLAN | B33: PLAN-01/RF1 | C33: Catalogo/listado visible de barcos | D33: Textual | E33: 1 | F33: 1 | G33: No | H33: =IF(AND(E33=1,F33=1),1,0) | I33: Aguas arriba: Registro/Matriz RF1. Aguas abajo: Product Backlog S3 RF1 Terminado; 02_ARQUITECTURA.md documenta app store con listado y detalle; 03_MODELO_DE_DATOS.md documenta Product.
A34: ART-B-PLAN | B34: PLAN-02/RNF1 | C34: Mecanismo para modificar tiempo/duracion de alquiler | D34: Textual | E34: 1 | F34: 1 | G34: No | H34: =IF(AND(E34=1,F34=1),1,0) | I34: Aguas arriba: Registro/Matriz RNF1. Aguas abajo: Product Backlog S3 RNF1 Terminado; 02_ARQUITECTURA.md documenta carts con CartItem y fechas; 03_MODELO_DE_DATOS.md documenta CartItem y OrderProduct con fechas de reserva.
A35: ART-B-PLAN | B35: PLAN-03/RF2 | C35: Categorias de barcos ofertadas | D35: Textual | E35: 1 | F35: 1 | G35: No | H35: =IF(AND(E35=1,F35=1),1,0) | I35: Aguas arriba: Registro/Matriz RF2. Aguas abajo: Product Backlog S3 RF2 Terminado; 02_ARQUITECTURA.md documenta app category y store; 03_MODELO_DE_DATOS.md documenta Category y ForeignKey Product->Category.
A36: ART-B-PLAN | B36: PLAN-04/RNF2 | C36: Modificacion de datos de cuenta del cliente | D36: Textual | E36: 1 | F36: 1 | G36: No | H36: =IF(AND(E36=1,F36=1),1,0) | I36: Aguas arriba: Registro/Matriz RNF2. Aguas abajo: Product Backlog S3 RNF2 Terminado; 02_ARQUITECTURA.md documenta accounts/views.py con dashboard/perfil y forms UserForm/UserProfileForm; 03_MODELO_DE_DATOS.md documenta UserProfile.
A37: ART-B-PLAN | B37: PLAN-05/RNF4 | C37: Interfaz en español | D37: Textual | E37: 1 | F37: 1 | G37: No | H37: =IF(AND(E37=1,F37=1),1,0) | I37: Aguas arriba: Registro/Matriz RNF4. Aguas abajo: Product Backlog S3 RNF4 Terminado; evidencia textual en plantillas y documentos del producto auditado, con templates globales descritos en 02_ARQUITECTURA.md.
A38: ART-B-PLAN | B38: PLAN-06/RF4 | C38: Login por correo y clave | D38: Textual | E38: 1 | F38: 1 | G38: No | H38: =IF(AND(E38=1,F38=1),1,0) | I38: Aguas arriba: Registro/Matriz RF4. Aguas abajo: Product Backlog S3 RF4 Terminado; 02_ARQUITECTURA.md documenta accounts con Register/login/logout; 03_MODELO_DE_DATOS.md documenta Account con USERNAME_FIELD=email.
A39: ART-B-PLAN | B39: PLAN-07/RF6 | C39: Marcado de barcos no disponibles | D39: Textual | E39: 1 | F39: 1 | G39: No | H39: =IF(AND(E39=1,F39=1),1,0) | I39: Aguas arriba: Registro/Matriz RF6. Aguas abajo: Product Backlog S3 RF6 Terminado; 03_MODELO_DE_DATOS.md documenta Product.is_available y stock; 02_ARQUITECTURA.md documenta store como catalogo/disponibilidad.
A40: ART-B-PLAN | B40: PLAN-08/RNF5 | C40: Datos de barco: capacidad, imagen, categoria, fabricante y puerto | D40: Textual | E40: 1 | F40: 1 | G40: No | H40: =IF(AND(E40=1,F40=1),1,0) | I40: Aguas arriba: Registro/Matriz RNF5. Aguas abajo: Product Backlog S3 RNF5 Terminado; 03_MODELO_DE_DATOS.md documenta Product con images, category, fabricante, puerto y capacidad.
A41: ART-B-PLAN | B41: PLAN-09/RF8 | C41: Catalogo por categorias y filtros | D41: Textual | E41: 1 | F41: 1 | G41: No | H41: =IF(AND(E41=1,F41=1),1,0) | I41: Aguas arriba: Registro/Matriz RF8. Aguas abajo: Product Backlog S3 RF8 Terminado; 02_ARQUITECTURA.md documenta store como catalogo, filtros de busqueda y navegacion por categorias.
A42: ART-B-PLAN | B42: PLAN-10/RF16a | C42: No devolucion de productos/alquileres | D42: Textual | E42: 1 | F42: 1 | G42: No | H42: =IF(AND(E42=1,F42=1),1,0) | I42: Aguas arriba: Registro/Matriz RF16. Aguas abajo: Product Backlog S3 mantiene RF16 Terminado; 03_MODELO_DE_DATOS.md documenta estados/ordenes y RNF8 cubre aviso de no devolucion asociado a cancelacion. | J42: Trazabilidad funcional, no por modulo aislado.
A43: ART-B-PLAN | B43: PLAN-11/RNF6 | C43: Marca corporativa y politicas visibles | D43: Textual | E43: 1 | F43: 0 | G43: No | H43: =IF(AND(E43=1,F43=1),1,0) | I43: Aguas arriba: Registro/Matriz RNF6. Aguas abajo: Product Backlog S3 lo marca Terminado, pero en la auditoria tecnica no hay evidencia especifica de politicas/brand content mas alla de plantillas estaticas genericas. | J43: Propuesto NO trazable: falta evidencia aguas abajo especifica.
A44: ART-B-PLAN | B44: PLAN-12/RF10 | C44: Solicitud de datos de usuario en el alquiler | D44: Textual | E44: 1 | F44: 1 | G44: No | H44: =IF(AND(E44=1,F44=1),1,0) | I44: Aguas arriba: Registro/Matriz RF10. Aguas abajo: Product Backlog S3 RF10 Terminado; 02_ARQUITECTURA.md documenta orders/forms.py OrderForm y templates de checkout; 03_MODELO_DE_DATOS.md documenta Order con datos asociados.
A45: ART-B-PLAN | B45: PLAN-13/RF11 | C45: Solicitud de datos de envio: hora, dia, puerto | D45: Textual | E45: 1 | F45: 1 | G45: No | H45: =IF(AND(E45=1,F45=1),1,0) | I45: Aguas arriba: Registro/Matriz RF11. Aguas abajo: Product Backlog S3 RF11 Terminado; 03_MODELO_DE_DATOS.md documenta Product.puerto y OrderProduct con fechas de reserva; 02_ARQUITECTURA.md documenta checkout en orders.
...

Sheet 02_R1_sintesis_artefactos
A1: R1 — Síntesis complementaria por artefacto (M1 oficial + M3/M4/M5)
A2: INSTRUCCIONES: Esta hoja resume la evaluación por artefacto. M1 nivel oficial se toma de 03b_R1_M1_resumen; la justificación M1 se conserva como explicación cualitativa. M3, M4 y M5 se registran aquí con sus evidencias y cálculos. Nota M1: la fuente oficial de completitud es 03_R1_M1_checklist + 03b_R1_M1_resumen. Esta hoja no recalcula M1; lo referencia para integrar todas las métricas por artefacto.
A4: ID artefacto | B4: Caso | C4: Run | D4: Familia | E4: Artefacto | F4: M1 (desde 03b) | G4: M1 justificación (complementaria) | H4: M3 nivel (0-3) | I4: M3 (# contradicciones) | J4: M3 justificación | K4: M4 (N total ítems) | L4: M4 (N ítems trazables) | M4: M4 % calculado | N4: M4 tramo | O4: M4 justificación | P4: M5 G1 | Q4: M5 G2 | R4: M5 G3 | S4: M5 G4 | T4: M5 Nivel (0-4)
A5: ART-B-REQ | B5: Baseline | C5: — | D5: Requisitos | E5: Registro Requisitos + Matriz Trazabilidad | F5: =IFERROR(INDEX('03b_R1_M1_resumen'!$I:$I,MATCH(A5,'03b_R1_M1_resumen'!$A:$A,0)),"") | G5: Registro y matriz contienen RF/RNF con ID, categoria, prioridad, criterio de aceptacion, interesado y trazabilidad basica; cobertura sustancial/completa de requisitos de alquiler, catalogo, reserva, pagos y administracion. | H5: 1 | I5: 3 | J5: Hay inconsistencias de identificacion entre Registro y Matriz: RF13/RF15/RF19 no aparecen igual en ambos documentos y el Registro salta numeracion tras RF16. No se detecta contradiccion funcional mayor. | K5: 28 | L5: 27 | M5: =IF(AND(K5>0,L5<>""),L5/K5*100,"") | N5: =IF(M5="","",IF(M5<25,"0-25 ausente/residual",IF(M5<50,"25-50 parcial",IF(M5<75,"50-75 sustancial","75-100 alta")))) | O5: Matriz incluye fuente/interesado, objetivo, entregable y criterio para la mayoria de requisitos; RF19 queda sin correspondencia clara en Registro/backlogs. | P5: 1 | Q5: 1 | R5: 1 | S5: 0 | T5: =SUM(P5:S5)
A6: ART-B-PLAN | B6: Baseline | C6: — | D6: Planificación | E6: Sprint Plannings + Product Backlogs S1-S2-S3 | F6: =IFERROR(INDEX('03b_R1_M1_resumen'!$I:$I,MATCH(A6,'03b_R1_M1_resumen'!$A:$A,0)),"") | G6: Sprint Plannings y Product Backlogs existen para los tres sprints, con issues/requisitos, estado y responsables. Falta granularidad de HU, criterios de aceptacion por historia y dependencias explicitas. | H6: 2 | I6: 2 | J6: Fallos menores: algunos documentos mantienen tipo documental incorrecto y hay cambios de pasarela/despliegue entre sprints, aunque quedan parcialmente justificados en planning/cierre. | K6: 30 | L6: 27 | M6: =IF(AND(K6>0,L6<>""),L6/K6*100,"") | N6: =IF(M6="","",IF(M6<25,"0-25 ausente/residual",IF(M6<50,"25-50 parcial",IF(M6<75,"50-75 sustancial","75-100 alta")))) | O6: Los Product Backlogs contienen 30 items trazados por ID a requisitos/sprints; algunos IDs no tienen correspondencia uniforme en Registro/Matriz. | P6: 1 | Q6: 1 | R6: 1 | S6: 0 | T6: =SUM(P6:S6)
A7: ART-B-DIS | B7: Baseline | C7: — | D7: Diseño técnico | E7: Auditoría posthoc 02_ARQUITECTURA + 03_MODELO_DATOS | F7: =IFERROR(INDEX('03b_R1_M1_resumen'!$I:$I,MATCH(A7,'03b_R1_M1_resumen'!$A:$A,0)),"") | G7: Los documentos posthoc 02_ARQUITECTURA y 03_MODELO_DE_DATOS describen stack, estructura, componentes y modelo de datos con suficiente cobertura tecnica del producto. | H7: 3 | I7: 0 | J7: No se observan contradicciones internas relevantes entre arquitectura y modelo de datos en la documentacion disponible. | K7: 2 | L7: 2 | M7: =IF(AND(K7>0,L7<>""),L7/K7*100,"") | N7: =IF(M7="","",IF(M7<25,"0-25 ausente/residual",IF(M7<50,"25-50 parcial",IF(M7<75,"50-75 sustancial","75-100 alta")))) | O7: Trazabilidad inferida por los dos documentos tecnicos: arquitectura y modelo de datos cubren componentes principales del sistema entregado. | P7: 0 | Q7: 0 | R7: 0 | S7: 0 | T7: =SUM(P7:S7)
A8: ART-B-SEG-S1 | B8: Baseline | C8: — | D8: Seguimiento | E8: Sprint Review 1 + Retrospective 1 | F8: =IFERROR(INDEX('03b_R1_M1_resumen'!$I:$I,MATCH(A8,'03b_R1_M1_resumen'!$A:$A,0)),"") | G8: Review y Retrospective del Sprint 1 existen, con acta, revision de tareas y acciones de mejora; el detalle de evidencias, metricas y aceptacion es limitado. | H8: 2 | I8: 1 | J8: Fallo menor documental: algunos encabezados identifican la review/retrospective como Sprint Planning. No afecta al contenido central. | K8: 2 | L8: 2 | M8: =IF(AND(K8>0,L8<>""),L8/K8*100,"") | N8: =IF(M8="","",IF(M8<25,"0-25 ausente/residual",IF(M8<50,"25-50 parcial",IF(M8<75,"50-75 sustancial","75-100 alta")))) | O8: Review y retrospectiva enlazan con el cierre del Sprint 1 y con las tareas planificadas, aunque sin trazabilidad itemizada. | P8: 1 | Q8: 0 | R8: 0 | S8: 1 | T8: =SUM(P8:S8)
A9: ART-B-SEG-S2 | B9: Baseline | C9: — | D9: Seguimiento | E9: Sprint Review 2 + Retrospective 2 | F9: =IFERROR(INDEX('03b_R1_M1_resumen'!$I:$I,MATCH(A9,'03b_R1_M1_resumen'!$A:$A,0)),"") | G9: Review y Retrospective del Sprint 2 existen e incluyen tareas no completadas, desviacion de horas y conflicto entre ramas; falta detalle itemizado de aceptacion. | H9: 2 | I9: 1 | J9: Fallo menor de consistencia documental por encabezado/tipo de documento; el contenido de seguimiento es coherente. | K9: 2 | L9: 2 | M9: =IF(AND(K9>0,L9<>""),L9/K9*100,"") | N9: =IF(M9="","",IF(M9<25,"0-25 ausente/residual",IF(M9<50,"25-50 parcial",IF(M9<75,"50-75 sustancial","75-100 alta")))) | O9: La review identifica tareas completadas/no completadas y la retrospectiva registra incidencia; trazabilidad suficiente a nivel de sprint. | P9: 1 | Q9: 1 | R9: 1 | S9: 1 | T9: =SUM(P9:S9)
A10: ART-B-SEG-S3 | B10: Baseline | C10: — | D10: Seguimiento | E10: Sprint Review 3 + Retrospective 3 | F10: =IFERROR(INDEX('03b_R1_M1_resumen'!$I:$I,MATCH(A10,'03b_R1_M1_resumen'!$A:$A,0)),"") | G10: Review y Retrospective del Sprint 3 existen y documentan cierre de tareas, desviaciones y aprendizajes; la evidencia sigue siendo resumida. | H10: 1 | I10: 2 | J10: Contradiccion factual menor de fechas en la retrospectiva del Sprint 3 frente a planning/review, y persistencia de encabezados no alineados. | K10: 2 | L10: 2 | M10: =IF(AND(K10>0,L10<>""),L10/K10*100,"") | N10: =IF(M10="","",IF(M10<25,"0-25 ausente/residual",IF(M10<50,"25-50 parcial",IF(M10<75,"50-75 sustancial","75-100 alta")))) | O10: La documentacion enlaza el Sprint 3 con tareas continuadas de pagos/seguimiento y cierre, sin matriz itemizada. | P10: 1 | Q10: 0 | R10: 1 | S10: 1 | T10: =SUM(P10:S10)
A11: ART-B-CIE | B11: Baseline | C11: — | D11: Cierre | E11: Lecciones Aprendidas + Informe de cierre | F11: =IFERROR(INDEX('03b_R1_M1_resumen'!$I:$I,MATCH(A11,'03b_R1_M1_resumen'!$A:$A,0)),"") | G11: Lecciones aprendidas e Informe de cierre existen y cubren desviaciones, costes, cronograma y recomendaciones, pero no incluyen aprobacion formal detallada ni trazabilidad exhaustiva. | H11: 3 | I11: 0 | J11: Los documentos de cierre son internamente coherentes: las desviaciones de pago, cronograma y costes se explican de forma consistente. | K11: 2 | L11: 2 | M11: =IF(AND(K11>0,L11<>""),L11/K11*100,"") | N11: =IF(M11="","",IF(M11<25,"0-25 ausente/residual",IF(M11<50,"25-50 parcial",IF(M11<75,"50-75 sustancial","75-100 alta")))) | O11: Informe de cierre y lecciones aprendidas enlazan con desviaciones, incidencias y recomendaciones finales del proyecto. | P11: 0 | Q11: 1 | R11: 1 | S11: 1 | T11: =SUM(P11:S11)
A12: ART-run_01-REQ | B12: Pipeline | C12: run_01 | D12: Requisitos | E12: registro_requisitos.json + .md | F12: =IFERROR(INDEX('03b_R1_M1_resumen'!$I:$I,MATCH(A12,'03b_R1_M1_resumen'!$A:$A,0)),"") | G12: registro_requisitos contiene 36 RF y 9 RNF con ID, descripcion y prioridad; cubre el alcance principal, aunque la prioridad es poco discriminante y algunos RNF estan agrupados. | H12: 2 | I12: 2 | J12: Gate 1 solo marca observaciones no bloqueantes: priorizacion poco informativa y granularidad limitada en seguridad/importe. | K12: 45 | L12: 45 | M12: =IF(AND(K12>0,L12<>""),L12/K12*100,"") | N12: =IF(M12="","",IF(M12<25,"0-25 ausente/residual",IF(M12<50,"25-50 parcial",IF(M12<75,"50-75 sustancial","75-100 alta")))) | O12: Todos los RF/RNF tienen correspondencia textual con el backlog generado y el gate acepta cobertura suficiente del brief. | P12: 1 | Q12: 0 | R12: 0 | S12: 1 | T12: =SUM(P12:S12)
A13: ART-run_01-PLAN | B13: Pipeline | C13: run_01 | D13: Planificación | E13: backlog + plan_sprints + riesgos | F13: =IFERROR(INDEX('03b_R1_M1_resumen'!$I:$I,MATCH(A13,'03b_R1_M1_resumen'!$A:$A,0)),"") | G13: backlog, plan_sprints y riesgos estan presentes; hay 21 HU, tres sprints y 10 riesgos. Falta enlace explicito requisito-HU en algunas historias. | H13: 2 | I13: 2 | J13: Gate 2 senala observaciones no bloqueantes sobre concentracion de complejidad, seed en Dockerfile y posible exceso con cron/Celery. | K13: 21 | L13: 21 | M13: =IF(AND(K13>0,L13<>""),L13/K13*100,"") | N13: =IF(M13="","",IF(M13<25,"0-25 ausente/residual",IF(M13<50,"25-50 parcial",IF(M13<75,"50-75 sustancial","75-100 alta")))) | O13: Las 21 HU aparecen planificadas en sprints y son trazables por contenido al registro de requisitos. | P13: 1 | Q13: 0 | R13: 0 | S13: 1 | T13: =SUM(P13:S13)
A14: ART-run_01-DIS | B14: Pipeline | C14: run_01 | D14: Diseño técnico | E14: diseno_tecnico.json + .md | F14: =IFERROR(INDEX('03b_R1_M1_resumen'!$I:$I,MATCH(A14,'03b_R1_M1_resumen'!$A:$A,0)),"") | G14: diseno_tecnico contiene stack, 6 apps Django, 8 modelos y 29 rutas; cubre el stack, la estructura de apps, el modelo de datos y las rutas necesarias para generar el producto. Gate 3 lo acepta con observaciones no bloqueantes. | H14: 2 | I14: 3 | J14: Gate 3 marca observaciones menores: ImageField declarado como cadena, posible confusi?n core/settings frente al paquete del proyecto, disponibilidad por fechas no derivada solo de Barco.disponible y logout GET preferible como POST. | K14: 37 | L14: 36 | M14: =IF(AND(K14>0,L14<>""),L14/K14*100,"") | N14: =IF(M14="","",IF(M14<25,"0-25 ausente/residual",IF(M14<50,"25-50 parcial",IF(M14<75,"50-75 sustancial","75-100 alta")))) | O14: 36 de 37 elementos de apps/modelos/rutas enlazan textualmente con requisitos o backlog; queda al menos un detalle t?cnico menos trazado/documentado de forma expl?cita. | P14: 1 | Q14: 0 | R14: 0 | S14: 1 | T14: =SUM(P14:S14)
A15: ART-run_01-SEG-S1 | B15: Pipeline | C15: run_01 | D15: Seguimiento | E15: review_sprint_1.json + .md | F15: =IFERROR(INDEX('03b_R1_M1_resumen'!$I:$I,MATCH(A15,'03b_R1_M1_resumen'!$A:$A,0)),"") | G15: review_sprint_1 incluye backlog pedido, archivos entregados, cumplimiento, arranque, rutas, templates e incidencias. | H15: 3 | I15: 0 | J15: No se detectan contradicciones internas; las incidencias estan registradas como seguimiento, no como incoherencias del artefacto. | K15: 8 | L15: 8 | M15: =IF(AND(K15>0,L15<>""),L15/K15*100,"") | N15: =IF(M15="","",IF(M15<25,"0-25 ausente/residual",IF(M15<50,"25-50 parcial",IF(M15<75,"50-75 sustancial","75-100 alta")))) | O15: Los 8 items pedidos del sprint aparecen en la review con evidencias de cumplimiento/entrega. | P15: 1 | Q15: 0 | R15: 1 | S15: 1 | T15: =SUM(P15:S15)
A16: ART-run_01-SEG-S2 | B16: Pipeline | C16: run_01 | D16: Seguimiento | E16: review_sprint_2.json + .md | F16: =IFERROR(INDEX('03b_R1_M1_resumen'!$I:$I,MATCH(A16,'03b_R1_M1_resumen'!$A:$A,0)),"") | G16: review_sprint_2 documenta 6 items pedidos, entregables, cumplimiento, arranque, rutas y templates; no registra incidencias. | H16: 3 | I16: 0 | J16: Artefacto coherente, sin contradicciones internas detectadas. | K16: 6 | L16: 6 | M16: =IF(AND(K16>0,L16<>""),L16/K16*100,"") | N16: =IF(M16="","",IF(M16<25,"0-25 ausente/residual",IF(M16<50,"25-50 parcial",IF(M16<75,"50-75 sustancial","75-100 alta")))) | O16: Los 6 items pedidos quedan enlazados con entregables y checks de la review. | P16: 1 | Q16: 0 | R16: 0 | S16: 1 | T16: =SUM(P16:S16)
... A32: ART-run_03-CIE | B32: Pipeline | C32: run_03 | D32: Cierre | E32: lecciones_aprendidas.md + review_final.md + readme.md | F32: =IFERROR(INDEX('03b_R1_M1_resumen'!$I:$I,MATCH(A32,'03b_R1_M1_resumen'!$A:$A,0)),"") | G32: Cierre con lecciones_aprendidas, review_final y readme; review_final muestra OK global y 16 checks ejecutados, pero las lecciones son genericas. | H32: 3 | I32: 0 | J32: Cierre coherente y sin incidencias finales. | K32: 3 | L32: 3 | M32: =IF(AND(K32>0,L32<>""),L32/K32*100,"") | N32: =IF(M32="","",IF(M32<25,"0-25 ausente/residual",IF(M32<50,"25-50 parcial",IF(M32<75,"50-75 sustancial","75-100 alta")))) | O32: Los tres documentos de cierre enlazan con validacion final, entrega y aprendizaje del run. | P32: 1 | Q32: 0 | R32: 0 | S32: 1 | T32: =SUM(P32:S32)
A34: Nota M5 (memoria, cap. 9): la huella de gobernanza acredita G1 (decisión) y G4 (aprobación) solo en fases con gate humano. En sprints y cierre del pipeline, sin gate, G1 y G4 no se acreditan.
A35: La media de M5 reportada es el promedio de las cinco familias. Baseline·Requisitos = 3 (G1,G2,G3,G4 = 1,1,1,0).
A36: Valores finales M5 (media por caso): Baseline 2,40 · Run 01 1,27 · Run 02 1,67 · Run 03 1,33. Media del pipeline 1,42.

Sheet 06_P1_P2_pruebas
